 
2019-10-20 17:02:45,098 - INFO - –ë–æ—Ç –∑–∞–ø—É—Å–∫–∞–µ—Ç—Å—è
2019-10-20 17:03:20,464 - INFO - –ü—Ä–∏–≤–µ—Ç üê∂
2019-10-20 17:03:42,090 - INFO - User: krimea_river, Chat id: 211751313, Message: –ë–∞—Ä—ç—Ñ!
2019-10-20 17:09:24,943 - INFO - Received signal 2 (SIGINT), stopping...
2019-10-20 17:09:27,555 - WARNING - Exiting immediately!
2019-10-20 17:09:35,446 - INFO - –ë–æ—Ç –∑–∞–ø—É—Å–∫–∞–µ—Ç—Å—è
2019-10-20 17:09:58,859 - INFO - User: krimea_river, Chat id: 211751313, Message: –ü—Ä–∏–≤–µ—Ç!!!
2019-10-20 17:10:16,873 - INFO - User: krimea_river, Chat id: 211751313, Message: –ö–∞–∫ —É —Ç–µ–±—è –¥–µ–ª–∞?
2019-10-20 17:23:15,920 - INFO - Received signal 2 (SIGINT), stopping...
2019-10-20 17:45:40,348 - INFO - –ë–æ—Ç –∑–∞–ø—É—Å–∫–∞–µ—Ç—Å—è
2019-10-20 17:45:47,271 - INFO - –ü—Ä–∏–≤–µ—Ç üò∫
2019-10-20 17:45:50,338 - INFO - –ü—Ä–∏–≤–µ—Ç üòà
2019-10-20 17:45:52,001 - INFO - –ü—Ä–∏–≤–µ—Ç üê∂
2019-10-20 17:46:02,286 - INFO - User: krimea_river, Chat id: 211751313, Message: rhino
2019-10-20 17:46:38,791 - ERROR - Error while getting Updates: urllib3 HTTPError ('Connection aborted.', RemoteDisconnected('Remote end closed connection without response'))
2019-10-20 17:46:38,792 - ERROR - No error handlers are registered, logging exception.
Traceback (most recent call last):
  File "/home/den/projects/megabot/env/lib/python3.7/site-packages/telegram/vendor/ptb_urllib3/urllib3/connectionpool.py", line 617, in urlopen
    chunked=chunked)
  File "/home/den/projects/megabot/env/lib/python3.7/site-packages/telegram/vendor/ptb_urllib3/urllib3/connectionpool.py", line 402, in _make_request
    six.raise_from(e, None)
  File "<string>", line 2, in raise_from
  File "/home/den/projects/megabot/env/lib/python3.7/site-packages/telegram/vendor/ptb_urllib3/urllib3/connectionpool.py", line 398, in _make_request
    httplib_response = conn.getresponse()
  File "/home/den/anaconda3/lib/python3.7/http/client.py", line 1321, in getresponse
    response.begin()
  File "/home/den/anaconda3/lib/python3.7/http/client.py", line 296, in begin
    version, status, reason = self._read_status()
  File "/home/den/anaconda3/lib/python3.7/http/client.py", line 265, in _read_status
    raise RemoteDisconnected("Remote end closed connection without"
http.client.RemoteDisconnected: Remote end closed connection without response

During handling of the above exception, another exception occurred:

Traceback (most recent call last):
  File "/home/den/projects/megabot/env/lib/python3.7/site-packages/telegram/utils/request.py", line 218, in _request_wrapper
    resp = self._con_pool.request(*args, **kwargs)
  File "/home/den/projects/megabot/env/lib/python3.7/site-packages/telegram/vendor/ptb_urllib3/urllib3/request.py", line 70, in request
    **urlopen_kw)
  File "/home/den/projects/megabot/env/lib/python3.7/site-packages/telegram/vendor/ptb_urllib3/urllib3/request.py", line 148, in request_encode_body
    return self.urlopen(method, url, **extra_kw)
  File "/home/den/projects/megabot/env/lib/python3.7/site-packages/telegram/vendor/ptb_urllib3/urllib3/poolmanager.py", line 244, in urlopen
    response = conn.urlopen(method, u.request_uri, **kw)
  File "/home/den/projects/megabot/env/lib/python3.7/site-packages/telegram/vendor/ptb_urllib3/urllib3/connectionpool.py", line 666, in urlopen
    _stacktrace=sys.exc_info()[2])
  File "/home/den/projects/megabot/env/lib/python3.7/site-packages/telegram/vendor/ptb_urllib3/urllib3/util/retry.py", line 347, in increment
    raise six.reraise(type(error), error, _stacktrace)
  File "/home/den/projects/megabot/env/lib/python3.7/site-packages/telegram/vendor/ptb_urllib3/urllib3/packages/six.py", line 685, in reraise
    raise value.with_traceback(tb)
  File "/home/den/projects/megabot/env/lib/python3.7/site-packages/telegram/vendor/ptb_urllib3/urllib3/connectionpool.py", line 617, in urlopen
    chunked=chunked)
  File "/home/den/projects/megabot/env/lib/python3.7/site-packages/telegram/vendor/ptb_urllib3/urllib3/connectionpool.py", line 402, in _make_request
    six.raise_from(e, None)
  File "<string>", line 2, in raise_from
  File "/home/den/projects/megabot/env/lib/python3.7/site-packages/telegram/vendor/ptb_urllib3/urllib3/connectionpool.py", line 398, in _make_request
    httplib_response = conn.getresponse()
  File "/home/den/anaconda3/lib/python3.7/http/client.py", line 1321, in getresponse
    response.begin()
  File "/home/den/anaconda3/lib/python3.7/http/client.py", line 296, in begin
    version, status, reason = self._read_status()
  File "/home/den/anaconda3/lib/python3.7/http/client.py", line 265, in _read_status
    raise RemoteDisconnected("Remote end closed connection without"
telegram.vendor.ptb_urllib3.urllib3.exceptions.ProtocolError: ('Connection aborted.', RemoteDisconnected('Remote end closed connection without response'))

During handling of the above exception, another exception occurred:

Traceback (most recent call last):
  File "/home/den/projects/megabot/env/lib/python3.7/site-packages/telegram/ext/updater.py", line 332, in _network_loop_retry
    if not action_cb():
  File "/home/den/projects/megabot/env/lib/python3.7/site-packages/telegram/ext/updater.py", line 293, in polling_action_cb
    allowed_updates=allowed_updates)
  File "/home/den/projects/megabot/env/lib/python3.7/site-packages/telegram/bot.py", line 66, in decorator
    result = func(self, *args, **kwargs)
  File "/home/den/projects/megabot/env/lib/python3.7/site-packages/telegram/bot.py", line 1983, in get_updates
    result = self._request.post(url, data, timeout=float(read_latency) + float(timeout))
  File "/home/den/projects/megabot/env/lib/python3.7/site-packages/telegram/utils/request.py", line 327, in post
    **urlopen_kwargs)
  File "/home/den/projects/megabot/env/lib/python3.7/site-packages/telegram/utils/request.py", line 224, in _request_wrapper
    raise NetworkError('urllib3 HTTPError {0}'.format(error))
telegram.error.NetworkError: urllib3 HTTPError ('Connection aborted.', RemoteDisconnected('Remote end closed connection without response'))
2019-10-20 17:58:08,158 - INFO - Received signal 2 (SIGINT), stopping...
2019-10-20 17:58:57,635 - INFO - –ë–æ—Ç –∑–∞–ø—É—Å–∫–∞–µ—Ç—Å—è
2019-10-20 17:59:07,970 - ERROR - No error handlers are registered, logging exception.
Traceback (most recent call last):
  File "/home/den/projects/megabot/env/lib/python3.7/site-packages/telegram/ext/dispatcher.py", line 372, in process_update
    handler.handle_update(update, self, check, context)
  File "/home/den/projects/megabot/env/lib/python3.7/site-packages/telegram/ext/handler.py", line 120, in handle_update
    return self.callback(dispatcher.bot, update, **optional_args)
  File "bot.py", line 22, in talk_to_me
    user_text = "–ü—Ä–∏–≤–µ—Ç {}! –¢—ã –Ω–∞–ø–∏—Å–∞–ª: {}".format(update.message.chat.first_name, user_data['emo'], update.message.text)
KeyError: 'emo'
2019-10-20 17:59:16,957 - INFO - –ü—Ä–∏–≤–µ—Ç üòà
2019-10-20 17:59:30,878 - ERROR - No error handlers are registered, logging exception.
Traceback (most recent call last):
  File "/home/den/projects/megabot/env/lib/python3.7/site-packages/telegram/ext/dispatcher.py", line 372, in process_update
    handler.handle_update(update, self, check, context)
  File "/home/den/projects/megabot/env/lib/python3.7/site-packages/telegram/ext/handler.py", line 120, in handle_update
    return self.callback(dispatcher.bot, update, **optional_args)
  File "bot.py", line 22, in talk_to_me
    user_text = "–ü—Ä–∏–≤–µ—Ç {}! –¢—ã –Ω–∞–ø–∏—Å–∞–ª: {}".format(update.message.chat.first_name, user_data['emo'], update.message.text)
KeyError: 'emo'
2019-10-20 17:59:39,543 - ERROR - Error while getting Updates: urllib3 HTTPError ('Connection aborted.', RemoteDisconnected('Remote end closed connection without response'))
2019-10-20 17:59:39,544 - ERROR - No error handlers are registered, logging exception.
Traceback (most recent call last):
  File "/home/den/projects/megabot/env/lib/python3.7/site-packages/telegram/vendor/ptb_urllib3/urllib3/connectionpool.py", line 617, in urlopen
    chunked=chunked)
  File "/home/den/projects/megabot/env/lib/python3.7/site-packages/telegram/vendor/ptb_urllib3/urllib3/connectionpool.py", line 402, in _make_request
    six.raise_from(e, None)
  File "<string>", line 2, in raise_from
  File "/home/den/projects/megabot/env/lib/python3.7/site-packages/telegram/vendor/ptb_urllib3/urllib3/connectionpool.py", line 398, in _make_request
    httplib_response = conn.getresponse()
  File "/home/den/anaconda3/lib/python3.7/http/client.py", line 1321, in getresponse
    response.begin()
  File "/home/den/anaconda3/lib/python3.7/http/client.py", line 296, in begin
    version, status, reason = self._read_status()
  File "/home/den/anaconda3/lib/python3.7/http/client.py", line 265, in _read_status
    raise RemoteDisconnected("Remote end closed connection without"
http.client.RemoteDisconnected: Remote end closed connection without response

During handling of the above exception, another exception occurred:

Traceback (most recent call last):
  File "/home/den/projects/megabot/env/lib/python3.7/site-packages/telegram/utils/request.py", line 218, in _request_wrapper
    resp = self._con_pool.request(*args, **kwargs)
  File "/home/den/projects/megabot/env/lib/python3.7/site-packages/telegram/vendor/ptb_urllib3/urllib3/request.py", line 70, in request
    **urlopen_kw)
  File "/home/den/projects/megabot/env/lib/python3.7/site-packages/telegram/vendor/ptb_urllib3/urllib3/request.py", line 148, in request_encode_body
    return self.urlopen(method, url, **extra_kw)
  File "/home/den/projects/megabot/env/lib/python3.7/site-packages/telegram/vendor/ptb_urllib3/urllib3/poolmanager.py", line 244, in urlopen
    response = conn.urlopen(method, u.request_uri, **kw)
  File "/home/den/projects/megabot/env/lib/python3.7/site-packages/telegram/vendor/ptb_urllib3/urllib3/connectionpool.py", line 666, in urlopen
    _stacktrace=sys.exc_info()[2])
  File "/home/den/projects/megabot/env/lib/python3.7/site-packages/telegram/vendor/ptb_urllib3/urllib3/util/retry.py", line 347, in increment
    raise six.reraise(type(error), error, _stacktrace)
  File "/home/den/projects/megabot/env/lib/python3.7/site-packages/telegram/vendor/ptb_urllib3/urllib3/packages/six.py", line 685, in reraise
    raise value.with_traceback(tb)
  File "/home/den/projects/megabot/env/lib/python3.7/site-packages/telegram/vendor/ptb_urllib3/urllib3/connectionpool.py", line 617, in urlopen
    chunked=chunked)
  File "/home/den/projects/megabot/env/lib/python3.7/site-packages/telegram/vendor/ptb_urllib3/urllib3/connectionpool.py", line 402, in _make_request
    six.raise_from(e, None)
  File "<string>", line 2, in raise_from
  File "/home/den/projects/megabot/env/lib/python3.7/site-packages/telegram/vendor/ptb_urllib3/urllib3/connectionpool.py", line 398, in _make_request
    httplib_response = conn.getresponse()
  File "/home/den/anaconda3/lib/python3.7/http/client.py", line 1321, in getresponse
    response.begin()
  File "/home/den/anaconda3/lib/python3.7/http/client.py", line 296, in begin
    version, status, reason = self._read_status()
  File "/home/den/anaconda3/lib/python3.7/http/client.py", line 265, in _read_status
    raise RemoteDisconnected("Remote end closed connection without"
telegram.vendor.ptb_urllib3.urllib3.exceptions.ProtocolError: ('Connection aborted.', RemoteDisconnected('Remote end closed connection without response'))

During handling of the above exception, another exception occurred:

Traceback (most recent call last):
  File "/home/den/projects/megabot/env/lib/python3.7/site-packages/telegram/ext/updater.py", line 332, in _network_loop_retry
    if not action_cb():
  File "/home/den/projects/megabot/env/lib/python3.7/site-packages/telegram/ext/updater.py", line 293, in polling_action_cb
    allowed_updates=allowed_updates)
  File "/home/den/projects/megabot/env/lib/python3.7/site-packages/telegram/bot.py", line 66, in decorator
    result = func(self, *args, **kwargs)
  File "/home/den/projects/megabot/env/lib/python3.7/site-packages/telegram/bot.py", line 1983, in get_updates
    result = self._request.post(url, data, timeout=float(read_latency) + float(timeout))
  File "/home/den/projects/megabot/env/lib/python3.7/site-packages/telegram/utils/request.py", line 327, in post
    **urlopen_kwargs)
  File "/home/den/projects/megabot/env/lib/python3.7/site-packages/telegram/utils/request.py", line 224, in _request_wrapper
    raise NetworkError('urllib3 HTTPError {0}'.format(error))
telegram.error.NetworkError: urllib3 HTTPError ('Connection aborted.', RemoteDisconnected('Remote end closed connection without response'))
2019-10-20 18:00:27,331 - ERROR - No error handlers are registered, logging exception.
Traceback (most recent call last):
  File "/home/den/projects/megabot/env/lib/python3.7/site-packages/telegram/ext/dispatcher.py", line 372, in process_update
    handler.handle_update(update, self, check, context)
  File "/home/den/projects/megabot/env/lib/python3.7/site-packages/telegram/ext/handler.py", line 120, in handle_update
    return self.callback(dispatcher.bot, update, **optional_args)
  File "bot.py", line 22, in talk_to_me
    user_text = "–ü—Ä–∏–≤–µ—Ç {}! –¢—ã –Ω–∞–ø–∏—Å–∞–ª: {}".format(update.message.chat.first_name, user_data['emo'], update.message.text)
KeyError: 'emo'
2019-10-20 18:00:38,735 - ERROR - Error while getting Updates: urllib3 HTTPError ('Connection aborted.', RemoteDisconnected('Remote end closed connection without response'))
2019-10-20 18:00:38,736 - ERROR - No error handlers are registered, logging exception.
Traceback (most recent call last):
  File "/home/den/projects/megabot/env/lib/python3.7/site-packages/telegram/vendor/ptb_urllib3/urllib3/connectionpool.py", line 617, in urlopen
    chunked=chunked)
  File "/home/den/projects/megabot/env/lib/python3.7/site-packages/telegram/vendor/ptb_urllib3/urllib3/connectionpool.py", line 402, in _make_request
    six.raise_from(e, None)
  File "<string>", line 2, in raise_from
  File "/home/den/projects/megabot/env/lib/python3.7/site-packages/telegram/vendor/ptb_urllib3/urllib3/connectionpool.py", line 398, in _make_request
    httplib_response = conn.getresponse()
  File "/home/den/anaconda3/lib/python3.7/http/client.py", line 1321, in getresponse
    response.begin()
  File "/home/den/anaconda3/lib/python3.7/http/client.py", line 296, in begin
    version, status, reason = self._read_status()
  File "/home/den/anaconda3/lib/python3.7/http/client.py", line 265, in _read_status
    raise RemoteDisconnected("Remote end closed connection without"
http.client.RemoteDisconnected: Remote end closed connection without response

During handling of the above exception, another exception occurred:

Traceback (most recent call last):
  File "/home/den/projects/megabot/env/lib/python3.7/site-packages/telegram/utils/request.py", line 218, in _request_wrapper
    resp = self._con_pool.request(*args, **kwargs)
  File "/home/den/projects/megabot/env/lib/python3.7/site-packages/telegram/vendor/ptb_urllib3/urllib3/request.py", line 70, in request
    **urlopen_kw)
  File "/home/den/projects/megabot/env/lib/python3.7/site-packages/telegram/vendor/ptb_urllib3/urllib3/request.py", line 148, in request_encode_body
    return self.urlopen(method, url, **extra_kw)
  File "/home/den/projects/megabot/env/lib/python3.7/site-packages/telegram/vendor/ptb_urllib3/urllib3/poolmanager.py", line 244, in urlopen
    response = conn.urlopen(method, u.request_uri, **kw)
  File "/home/den/projects/megabot/env/lib/python3.7/site-packages/telegram/vendor/ptb_urllib3/urllib3/connectionpool.py", line 666, in urlopen
    _stacktrace=sys.exc_info()[2])
  File "/home/den/projects/megabot/env/lib/python3.7/site-packages/telegram/vendor/ptb_urllib3/urllib3/util/retry.py", line 347, in increment
    raise six.reraise(type(error), error, _stacktrace)
  File "/home/den/projects/megabot/env/lib/python3.7/site-packages/telegram/vendor/ptb_urllib3/urllib3/packages/six.py", line 685, in reraise
    raise value.with_traceback(tb)
  File "/home/den/projects/megabot/env/lib/python3.7/site-packages/telegram/vendor/ptb_urllib3/urllib3/connectionpool.py", line 617, in urlopen
    chunked=chunked)
  File "/home/den/projects/megabot/env/lib/python3.7/site-packages/telegram/vendor/ptb_urllib3/urllib3/connectionpool.py", line 402, in _make_request
    six.raise_from(e, None)
  File "<string>", line 2, in raise_from
  File "/home/den/projects/megabot/env/lib/python3.7/site-packages/telegram/vendor/ptb_urllib3/urllib3/connectionpool.py", line 398, in _make_request
    httplib_response = conn.getresponse()
  File "/home/den/anaconda3/lib/python3.7/http/client.py", line 1321, in getresponse
    response.begin()
  File "/home/den/anaconda3/lib/python3.7/http/client.py", line 296, in begin
    version, status, reason = self._read_status()
  File "/home/den/anaconda3/lib/python3.7/http/client.py", line 265, in _read_status
    raise RemoteDisconnected("Remote end closed connection without"
telegram.vendor.ptb_urllib3.urllib3.exceptions.ProtocolError: ('Connection aborted.', RemoteDisconnected('Remote end closed connection without response'))

During handling of the above exception, another exception occurred:

Traceback (most recent call last):
  File "/home/den/projects/megabot/env/lib/python3.7/site-packages/telegram/ext/updater.py", line 332, in _network_loop_retry
    if not action_cb():
  File "/home/den/projects/megabot/env/lib/python3.7/site-packages/telegram/ext/updater.py", line 293, in polling_action_cb
    allowed_updates=allowed_updates)
  File "/home/den/projects/megabot/env/lib/python3.7/site-packages/telegram/bot.py", line 66, in decorator
    result = func(self, *args, **kwargs)
  File "/home/den/projects/megabot/env/lib/python3.7/site-packages/telegram/bot.py", line 1983, in get_updates
    result = self._request.post(url, data, timeout=float(read_latency) + float(timeout))
  File "/home/den/projects/megabot/env/lib/python3.7/site-packages/telegram/utils/request.py", line 327, in post
    **urlopen_kwargs)
  File "/home/den/projects/megabot/env/lib/python3.7/site-packages/telegram/utils/request.py", line 224, in _request_wrapper
    raise NetworkError('urllib3 HTTPError {0}'.format(error))
telegram.error.NetworkError: urllib3 HTTPError ('Connection aborted.', RemoteDisconnected('Remote end closed connection without response'))
2019-10-20 18:01:14,886 - INFO - –ü—Ä–∏–≤–µ—Ç üò∫
2019-10-20 18:01:18,709 - ERROR - No error handlers are registered, logging exception.
Traceback (most recent call last):
  File "/home/den/projects/megabot/env/lib/python3.7/site-packages/telegram/ext/dispatcher.py", line 372, in process_update
    handler.handle_update(update, self, check, context)
  File "/home/den/projects/megabot/env/lib/python3.7/site-packages/telegram/ext/handler.py", line 120, in handle_update
    return self.callback(dispatcher.bot, update, **optional_args)
  File "bot.py", line 22, in talk_to_me
    user_text = "–ü—Ä–∏–≤–µ—Ç {}! –¢—ã –Ω–∞–ø–∏—Å–∞–ª: {}".format(update.message.chat.first_name, user_data['emo'], update.message.text)
KeyError: 'emo'
2019-10-20 18:01:38,952 - ERROR - Error while getting Updates: urllib3 HTTPError ('Connection aborted.', RemoteDisconnected('Remote end closed connection without response'))
2019-10-20 18:01:38,953 - ERROR - No error handlers are registered, logging exception.
Traceback (most recent call last):
  File "/home/den/projects/megabot/env/lib/python3.7/site-packages/telegram/vendor/ptb_urllib3/urllib3/connectionpool.py", line 617, in urlopen
    chunked=chunked)
  File "/home/den/projects/megabot/env/lib/python3.7/site-packages/telegram/vendor/ptb_urllib3/urllib3/connectionpool.py", line 402, in _make_request
    six.raise_from(e, None)
  File "<string>", line 2, in raise_from
  File "/home/den/projects/megabot/env/lib/python3.7/site-packages/telegram/vendor/ptb_urllib3/urllib3/connectionpool.py", line 398, in _make_request
    httplib_response = conn.getresponse()
  File "/home/den/anaconda3/lib/python3.7/http/client.py", line 1321, in getresponse
    response.begin()
  File "/home/den/anaconda3/lib/python3.7/http/client.py", line 296, in begin
    version, status, reason = self._read_status()
  File "/home/den/anaconda3/lib/python3.7/http/client.py", line 265, in _read_status
    raise RemoteDisconnected("Remote end closed connection without"
http.client.RemoteDisconnected: Remote end closed connection without response

During handling of the above exception, another exception occurred:

Traceback (most recent call last):
  File "/home/den/projects/megabot/env/lib/python3.7/site-packages/telegram/utils/request.py", line 218, in _request_wrapper
    resp = self._con_pool.request(*args, **kwargs)
  File "/home/den/projects/megabot/env/lib/python3.7/site-packages/telegram/vendor/ptb_urllib3/urllib3/request.py", line 70, in request
    **urlopen_kw)
  File "/home/den/projects/megabot/env/lib/python3.7/site-packages/telegram/vendor/ptb_urllib3/urllib3/request.py", line 148, in request_encode_body
    return self.urlopen(method, url, **extra_kw)
  File "/home/den/projects/megabot/env/lib/python3.7/site-packages/telegram/vendor/ptb_urllib3/urllib3/poolmanager.py", line 244, in urlopen
    response = conn.urlopen(method, u.request_uri, **kw)
  File "/home/den/projects/megabot/env/lib/python3.7/site-packages/telegram/vendor/ptb_urllib3/urllib3/connectionpool.py", line 666, in urlopen
    _stacktrace=sys.exc_info()[2])
  File "/home/den/projects/megabot/env/lib/python3.7/site-packages/telegram/vendor/ptb_urllib3/urllib3/util/retry.py", line 347, in increment
    raise six.reraise(type(error), error, _stacktrace)
  File "/home/den/projects/megabot/env/lib/python3.7/site-packages/telegram/vendor/ptb_urllib3/urllib3/packages/six.py", line 685, in reraise
    raise value.with_traceback(tb)
  File "/home/den/projects/megabot/env/lib/python3.7/site-packages/telegram/vendor/ptb_urllib3/urllib3/connectionpool.py", line 617, in urlopen
    chunked=chunked)
  File "/home/den/projects/megabot/env/lib/python3.7/site-packages/telegram/vendor/ptb_urllib3/urllib3/connectionpool.py", line 402, in _make_request
    six.raise_from(e, None)
  File "<string>", line 2, in raise_from
  File "/home/den/projects/megabot/env/lib/python3.7/site-packages/telegram/vendor/ptb_urllib3/urllib3/connectionpool.py", line 398, in _make_request
    httplib_response = conn.getresponse()
  File "/home/den/anaconda3/lib/python3.7/http/client.py", line 1321, in getresponse
    response.begin()
  File "/home/den/anaconda3/lib/python3.7/http/client.py", line 296, in begin
    version, status, reason = self._read_status()
  File "/home/den/anaconda3/lib/python3.7/http/client.py", line 265, in _read_status
    raise RemoteDisconnected("Remote end closed connection without"
telegram.vendor.ptb_urllib3.urllib3.exceptions.ProtocolError: ('Connection aborted.', RemoteDisconnected('Remote end closed connection without response'))

During handling of the above exception, another exception occurred:

Traceback (most recent call last):
  File "/home/den/projects/megabot/env/lib/python3.7/site-packages/telegram/ext/updater.py", line 332, in _network_loop_retry
    if not action_cb():
  File "/home/den/projects/megabot/env/lib/python3.7/site-packages/telegram/ext/updater.py", line 293, in polling_action_cb
    allowed_updates=allowed_updates)
  File "/home/den/projects/megabot/env/lib/python3.7/site-packages/telegram/bot.py", line 66, in decorator
    result = func(self, *args, **kwargs)
  File "/home/den/projects/megabot/env/lib/python3.7/site-packages/telegram/bot.py", line 1983, in get_updates
    result = self._request.post(url, data, timeout=float(read_latency) + float(timeout))
  File "/home/den/projects/megabot/env/lib/python3.7/site-packages/telegram/utils/request.py", line 327, in post
    **urlopen_kwargs)
  File "/home/den/projects/megabot/env/lib/python3.7/site-packages/telegram/utils/request.py", line 224, in _request_wrapper
    raise NetworkError('urllib3 HTTPError {0}'.format(error))
telegram.error.NetworkError: urllib3 HTTPError ('Connection aborted.', RemoteDisconnected('Remote end closed connection without response'))
2019-10-20 18:02:39,141 - ERROR - Error while getting Updates: urllib3 HTTPError ('Connection aborted.', RemoteDisconnected('Remote end closed connection without response'))
2019-10-20 18:02:39,142 - ERROR - No error handlers are registered, logging exception.
Traceback (most recent call last):
  File "/home/den/projects/megabot/env/lib/python3.7/site-packages/telegram/vendor/ptb_urllib3/urllib3/connectionpool.py", line 617, in urlopen
    chunked=chunked)
  File "/home/den/projects/megabot/env/lib/python3.7/site-packages/telegram/vendor/ptb_urllib3/urllib3/connectionpool.py", line 402, in _make_request
    six.raise_from(e, None)
  File "<string>", line 2, in raise_from
  File "/home/den/projects/megabot/env/lib/python3.7/site-packages/telegram/vendor/ptb_urllib3/urllib3/connectionpool.py", line 398, in _make_request
    httplib_response = conn.getresponse()
  File "/home/den/anaconda3/lib/python3.7/http/client.py", line 1321, in getresponse
    response.begin()
  File "/home/den/anaconda3/lib/python3.7/http/client.py", line 296, in begin
    version, status, reason = self._read_status()
  File "/home/den/anaconda3/lib/python3.7/http/client.py", line 265, in _read_status
    raise RemoteDisconnected("Remote end closed connection without"
http.client.RemoteDisconnected: Remote end closed connection without response

During handling of the above exception, another exception occurred:

Traceback (most recent call last):
  File "/home/den/projects/megabot/env/lib/python3.7/site-packages/telegram/utils/request.py", line 218, in _request_wrapper
    resp = self._con_pool.request(*args, **kwargs)
  File "/home/den/projects/megabot/env/lib/python3.7/site-packages/telegram/vendor/ptb_urllib3/urllib3/request.py", line 70, in request
    **urlopen_kw)
  File "/home/den/projects/megabot/env/lib/python3.7/site-packages/telegram/vendor/ptb_urllib3/urllib3/request.py", line 148, in request_encode_body
    return self.urlopen(method, url, **extra_kw)
  File "/home/den/projects/megabot/env/lib/python3.7/site-packages/telegram/vendor/ptb_urllib3/urllib3/poolmanager.py", line 244, in urlopen
    response = conn.urlopen(method, u.request_uri, **kw)
  File "/home/den/projects/megabot/env/lib/python3.7/site-packages/telegram/vendor/ptb_urllib3/urllib3/connectionpool.py", line 666, in urlopen
    _stacktrace=sys.exc_info()[2])
  File "/home/den/projects/megabot/env/lib/python3.7/site-packages/telegram/vendor/ptb_urllib3/urllib3/util/retry.py", line 347, in increment
    raise six.reraise(type(error), error, _stacktrace)
  File "/home/den/projects/megabot/env/lib/python3.7/site-packages/telegram/vendor/ptb_urllib3/urllib3/packages/six.py", line 685, in reraise
    raise value.with_traceback(tb)
  File "/home/den/projects/megabot/env/lib/python3.7/site-packages/telegram/vendor/ptb_urllib3/urllib3/connectionpool.py", line 617, in urlopen
    chunked=chunked)
  File "/home/den/projects/megabot/env/lib/python3.7/site-packages/telegram/vendor/ptb_urllib3/urllib3/connectionpool.py", line 402, in _make_request
    six.raise_from(e, None)
  File "<string>", line 2, in raise_from
  File "/home/den/projects/megabot/env/lib/python3.7/site-packages/telegram/vendor/ptb_urllib3/urllib3/connectionpool.py", line 398, in _make_request
    httplib_response = conn.getresponse()
  File "/home/den/anaconda3/lib/python3.7/http/client.py", line 1321, in getresponse
    response.begin()
  File "/home/den/anaconda3/lib/python3.7/http/client.py", line 296, in begin
    version, status, reason = self._read_status()
  File "/home/den/anaconda3/lib/python3.7/http/client.py", line 265, in _read_status
    raise RemoteDisconnected("Remote end closed connection without"
telegram.vendor.ptb_urllib3.urllib3.exceptions.ProtocolError: ('Connection aborted.', RemoteDisconnected('Remote end closed connection without response'))

During handling of the above exception, another exception occurred:

Traceback (most recent call last):
  File "/home/den/projects/megabot/env/lib/python3.7/site-packages/telegram/ext/updater.py", line 332, in _network_loop_retry
    if not action_cb():
  File "/home/den/projects/megabot/env/lib/python3.7/site-packages/telegram/ext/updater.py", line 293, in polling_action_cb
    allowed_updates=allowed_updates)
  File "/home/den/projects/megabot/env/lib/python3.7/site-packages/telegram/bot.py", line 66, in decorator
    result = func(self, *args, **kwargs)
  File "/home/den/projects/megabot/env/lib/python3.7/site-packages/telegram/bot.py", line 1983, in get_updates
    result = self._request.post(url, data, timeout=float(read_latency) + float(timeout))
  File "/home/den/projects/megabot/env/lib/python3.7/site-packages/telegram/utils/request.py", line 327, in post
    **urlopen_kwargs)
  File "/home/den/projects/megabot/env/lib/python3.7/site-packages/telegram/utils/request.py", line 224, in _request_wrapper
    raise NetworkError('urllib3 HTTPError {0}'.format(error))
telegram.error.NetworkError: urllib3 HTTPError ('Connection aborted.', RemoteDisconnected('Remote end closed connection without response'))
2019-10-20 18:03:39,330 - ERROR - Error while getting Updates: urllib3 HTTPError ('Connection aborted.', RemoteDisconnected('Remote end closed connection without response'))
2019-10-20 18:03:39,331 - ERROR - No error handlers are registered, logging exception.
Traceback (most recent call last):
  File "/home/den/projects/megabot/env/lib/python3.7/site-packages/telegram/vendor/ptb_urllib3/urllib3/connectionpool.py", line 617, in urlopen
    chunked=chunked)
  File "/home/den/projects/megabot/env/lib/python3.7/site-packages/telegram/vendor/ptb_urllib3/urllib3/connectionpool.py", line 402, in _make_request
    six.raise_from(e, None)
  File "<string>", line 2, in raise_from
  File "/home/den/projects/megabot/env/lib/python3.7/site-packages/telegram/vendor/ptb_urllib3/urllib3/connectionpool.py", line 398, in _make_request
    httplib_response = conn.getresponse()
  File "/home/den/anaconda3/lib/python3.7/http/client.py", line 1321, in getresponse
    response.begin()
  File "/home/den/anaconda3/lib/python3.7/http/client.py", line 296, in begin
    version, status, reason = self._read_status()
  File "/home/den/anaconda3/lib/python3.7/http/client.py", line 265, in _read_status
    raise RemoteDisconnected("Remote end closed connection without"
http.client.RemoteDisconnected: Remote end closed connection without response

During handling of the above exception, another exception occurred:

Traceback (most recent call last):
  File "/home/den/projects/megabot/env/lib/python3.7/site-packages/telegram/utils/request.py", line 218, in _request_wrapper
    resp = self._con_pool.request(*args, **kwargs)
  File "/home/den/projects/megabot/env/lib/python3.7/site-packages/telegram/vendor/ptb_urllib3/urllib3/request.py", line 70, in request
    **urlopen_kw)
  File "/home/den/projects/megabot/env/lib/python3.7/site-packages/telegram/vendor/ptb_urllib3/urllib3/request.py", line 148, in request_encode_body
    return self.urlopen(method, url, **extra_kw)
  File "/home/den/projects/megabot/env/lib/python3.7/site-packages/telegram/vendor/ptb_urllib3/urllib3/poolmanager.py", line 244, in urlopen
    response = conn.urlopen(method, u.request_uri, **kw)
  File "/home/den/projects/megabot/env/lib/python3.7/site-packages/telegram/vendor/ptb_urllib3/urllib3/connectionpool.py", line 666, in urlopen
    _stacktrace=sys.exc_info()[2])
  File "/home/den/projects/megabot/env/lib/python3.7/site-packages/telegram/vendor/ptb_urllib3/urllib3/util/retry.py", line 347, in increment
    raise six.reraise(type(error), error, _stacktrace)
  File "/home/den/projects/megabot/env/lib/python3.7/site-packages/telegram/vendor/ptb_urllib3/urllib3/packages/six.py", line 685, in reraise
    raise value.with_traceback(tb)
  File "/home/den/projects/megabot/env/lib/python3.7/site-packages/telegram/vendor/ptb_urllib3/urllib3/connectionpool.py", line 617, in urlopen
    chunked=chunked)
  File "/home/den/projects/megabot/env/lib/python3.7/site-packages/telegram/vendor/ptb_urllib3/urllib3/connectionpool.py", line 402, in _make_request
    six.raise_from(e, None)
  File "<string>", line 2, in raise_from
  File "/home/den/projects/megabot/env/lib/python3.7/site-packages/telegram/vendor/ptb_urllib3/urllib3/connectionpool.py", line 398, in _make_request
    httplib_response = conn.getresponse()
  File "/home/den/anaconda3/lib/python3.7/http/client.py", line 1321, in getresponse
    response.begin()
  File "/home/den/anaconda3/lib/python3.7/http/client.py", line 296, in begin
    version, status, reason = self._read_status()
  File "/home/den/anaconda3/lib/python3.7/http/client.py", line 265, in _read_status
    raise RemoteDisconnected("Remote end closed connection without"
telegram.vendor.ptb_urllib3.urllib3.exceptions.ProtocolError: ('Connection aborted.', RemoteDisconnected('Remote end closed connection without response'))

During handling of the above exception, another exception occurred:

Traceback (most recent call last):
  File "/home/den/projects/megabot/env/lib/python3.7/site-packages/telegram/ext/updater.py", line 332, in _network_loop_retry
    if not action_cb():
  File "/home/den/projects/megabot/env/lib/python3.7/site-packages/telegram/ext/updater.py", line 293, in polling_action_cb
    allowed_updates=allowed_updates)
  File "/home/den/projects/megabot/env/lib/python3.7/site-packages/telegram/bot.py", line 66, in decorator
    result = func(self, *args, **kwargs)
  File "/home/den/projects/megabot/env/lib/python3.7/site-packages/telegram/bot.py", line 1983, in get_updates
    result = self._request.post(url, data, timeout=float(read_latency) + float(timeout))
  File "/home/den/projects/megabot/env/lib/python3.7/site-packages/telegram/utils/request.py", line 327, in post
    **urlopen_kwargs)
  File "/home/den/projects/megabot/env/lib/python3.7/site-packages/telegram/utils/request.py", line 224, in _request_wrapper
    raise NetworkError('urllib3 HTTPError {0}'.format(error))
telegram.error.NetworkError: urllib3 HTTPError ('Connection aborted.', RemoteDisconnected('Remote end closed connection without response'))
2019-10-20 18:04:39,524 - ERROR - Error while getting Updates: urllib3 HTTPError ('Connection aborted.', RemoteDisconnected('Remote end closed connection without response'))
2019-10-20 18:04:39,525 - ERROR - No error handlers are registered, logging exception.
Traceback (most recent call last):
  File "/home/den/projects/megabot/env/lib/python3.7/site-packages/telegram/vendor/ptb_urllib3/urllib3/connectionpool.py", line 617, in urlopen
    chunked=chunked)
  File "/home/den/projects/megabot/env/lib/python3.7/site-packages/telegram/vendor/ptb_urllib3/urllib3/connectionpool.py", line 402, in _make_request
    six.raise_from(e, None)
  File "<string>", line 2, in raise_from
  File "/home/den/projects/megabot/env/lib/python3.7/site-packages/telegram/vendor/ptb_urllib3/urllib3/connectionpool.py", line 398, in _make_request
    httplib_response = conn.getresponse()
  File "/home/den/anaconda3/lib/python3.7/http/client.py", line 1321, in getresponse
    response.begin()
  File "/home/den/anaconda3/lib/python3.7/http/client.py", line 296, in begin
    version, status, reason = self._read_status()
  File "/home/den/anaconda3/lib/python3.7/http/client.py", line 265, in _read_status
    raise RemoteDisconnected("Remote end closed connection without"
http.client.RemoteDisconnected: Remote end closed connection without response

During handling of the above exception, another exception occurred:

Traceback (most recent call last):
  File "/home/den/projects/megabot/env/lib/python3.7/site-packages/telegram/utils/request.py", line 218, in _request_wrapper
    resp = self._con_pool.request(*args, **kwargs)
  File "/home/den/projects/megabot/env/lib/python3.7/site-packages/telegram/vendor/ptb_urllib3/urllib3/request.py", line 70, in request
    **urlopen_kw)
  File "/home/den/projects/megabot/env/lib/python3.7/site-packages/telegram/vendor/ptb_urllib3/urllib3/request.py", line 148, in request_encode_body
    return self.urlopen(method, url, **extra_kw)
  File "/home/den/projects/megabot/env/lib/python3.7/site-packages/telegram/vendor/ptb_urllib3/urllib3/poolmanager.py", line 244, in urlopen
    response = conn.urlopen(method, u.request_uri, **kw)
  File "/home/den/projects/megabot/env/lib/python3.7/site-packages/telegram/vendor/ptb_urllib3/urllib3/connectionpool.py", line 666, in urlopen
    _stacktrace=sys.exc_info()[2])
  File "/home/den/projects/megabot/env/lib/python3.7/site-packages/telegram/vendor/ptb_urllib3/urllib3/util/retry.py", line 347, in increment
    raise six.reraise(type(error), error, _stacktrace)
  File "/home/den/projects/megabot/env/lib/python3.7/site-packages/telegram/vendor/ptb_urllib3/urllib3/packages/six.py", line 685, in reraise
    raise value.with_traceback(tb)
  File "/home/den/projects/megabot/env/lib/python3.7/site-packages/telegram/vendor/ptb_urllib3/urllib3/connectionpool.py", line 617, in urlopen
    chunked=chunked)
  File "/home/den/projects/megabot/env/lib/python3.7/site-packages/telegram/vendor/ptb_urllib3/urllib3/connectionpool.py", line 402, in _make_request
    six.raise_from(e, None)
  File "<string>", line 2, in raise_from
  File "/home/den/projects/megabot/env/lib/python3.7/site-packages/telegram/vendor/ptb_urllib3/urllib3/connectionpool.py", line 398, in _make_request
    httplib_response = conn.getresponse()
  File "/home/den/anaconda3/lib/python3.7/http/client.py", line 1321, in getresponse
    response.begin()
  File "/home/den/anaconda3/lib/python3.7/http/client.py", line 296, in begin
    version, status, reason = self._read_status()
  File "/home/den/anaconda3/lib/python3.7/http/client.py", line 265, in _read_status
    raise RemoteDisconnected("Remote end closed connection without"
telegram.vendor.ptb_urllib3.urllib3.exceptions.ProtocolError: ('Connection aborted.', RemoteDisconnected('Remote end closed connection without response'))

During handling of the above exception, another exception occurred:

Traceback (most recent call last):
  File "/home/den/projects/megabot/env/lib/python3.7/site-packages/telegram/ext/updater.py", line 332, in _network_loop_retry
    if not action_cb():
  File "/home/den/projects/megabot/env/lib/python3.7/site-packages/telegram/ext/updater.py", line 293, in polling_action_cb
    allowed_updates=allowed_updates)
  File "/home/den/projects/megabot/env/lib/python3.7/site-packages/telegram/bot.py", line 66, in decorator
    result = func(self, *args, **kwargs)
  File "/home/den/projects/megabot/env/lib/python3.7/site-packages/telegram/bot.py", line 1983, in get_updates
    result = self._request.post(url, data, timeout=float(read_latency) + float(timeout))
  File "/home/den/projects/megabot/env/lib/python3.7/site-packages/telegram/utils/request.py", line 327, in post
    **urlopen_kwargs)
  File "/home/den/projects/megabot/env/lib/python3.7/site-packages/telegram/utils/request.py", line 224, in _request_wrapper
    raise NetworkError('urllib3 HTTPError {0}'.format(error))
telegram.error.NetworkError: urllib3 HTTPError ('Connection aborted.', RemoteDisconnected('Remote end closed connection without response'))
2019-10-20 18:06:02,875 - INFO - Received signal 2 (SIGINT), stopping...
2019-10-20 18:06:45,066 - INFO - –ë–æ—Ç –∑–∞–ø—É—Å–∫–∞–µ—Ç—Å—è
2019-10-20 18:06:50,844 - INFO - –ü—Ä–∏–≤–µ—Ç üòà
2019-10-20 18:07:02,877 - INFO - User: krimea_river, Chat id: 211751313, Message: –ü–†—ã—å–ø–æ—Ä—ã–ª–ø—Ä—ã–ª–ø—Ä–≤
2019-10-20 18:07:11,590 - INFO - User: krimea_river, Chat id: 211751313, Message: —ã—Ñ–≤—ã—Ü–≥–≤—ã—à–≥–≤\
2019-10-20 18:08:23,277 - INFO - User: krimea_river, Chat id: 211751313, Message: —ã—Ñ–≤—Ñ—ã–≤
2019-10-20 18:08:28,502 - INFO - Received signal 2 (SIGINT), stopping...
2019-10-20 18:08:35,587 - INFO - –ë–æ—Ç –∑–∞–ø—É—Å–∫–∞–µ—Ç—Å—è
2019-10-20 18:08:42,053 - ERROR - No error handlers are registered, logging exception.
Traceback (most recent call last):
  File "/home/den/projects/megabot/env/lib/python3.7/site-packages/telegram/ext/dispatcher.py", line 372, in process_update
    handler.handle_update(update, self, check, context)
  File "/home/den/projects/megabot/env/lib/python3.7/site-packages/telegram/ext/handler.py", line 120, in handle_update
    return self.callback(dispatcher.bot, update, **optional_args)
  File "bot.py", line 23, in talk_to_me
    user_text = "–ü—Ä–∏–≤–µ—Ç {}{}! –¢—ã –Ω–∞–ø–∏—Å–∞–ª: {}".format(update.message.chat.first_name, user_data['emo'],
KeyError: 'emo'
2019-10-20 18:08:55,148 - INFO - –ü—Ä–∏–≤–µ—Ç üêº
2019-10-20 18:11:11,144 - INFO - User: krimea_river, Chat id: 211751313, Message: –≤–∞—ã–≤–∞
2019-10-20 18:11:14,927 - INFO - User: krimea_river, Chat id: 211751313, Message: —ã–≤–∞—ã–≤–∞–æ–ª—ã–æ–≤–∞
2019-10-20 18:11:16,376 - INFO - User: krimea_river, Chat id: 211751313, Message: —ã–≤–∞–æ–ø—Ä–æ–∞—ã–≤–ø—Ä–∞–ø
2019-10-20 18:11:18,341 - INFO - User: krimea_river, Chat id: 211751313, Message: –∞—ã–ø–æ—Ä–≤—ã–∞–ª–æ—Ä–≤–ø—Ä–∫–ª–≥–ø—Ä–≤–ª–∫–≥–ø—Ç–∫–ø
2019-10-20 18:11:20,401 - INFO - User: krimea_river, Chat id: 211751313, Message: —á–±–¥–∞–ø—å–±–º–∏—å–±—Å–º—å–∏—Å—å–º–∏
2019-10-20 18:11:23,201 - INFO - User: krimea_river, Chat id: 211751313, Message: —ã—ã—Ç–º–ª–æ—Ä–∞–ª–æ—Ä—ã–≤–∞—ã–≤–∞
2019-10-20 18:14:30,846 - INFO - Received signal 2 (SIGINT), stopping...
2019-10-20 18:14:43,247 - INFO - –ë–æ—Ç –∑–∞–ø—É—Å–∫–∞–µ—Ç—Å—è
2019-10-20 18:14:49,124 - ERROR - No error handlers are registered, logging exception.
Traceback (most recent call last):
  File "/home/den/projects/megabot/env/lib/python3.7/site-packages/telegram/ext/dispatcher.py", line 372, in process_update
    handler.handle_update(update, self, check, context)
  File "/home/den/projects/megabot/env/lib/python3.7/site-packages/telegram/ext/handler.py", line 120, in handle_update
    return self.callback(dispatcher.bot, update, **optional_args)
  File "bot.py", line 23, in talk_to_me
    user_text = "–ü—Ä–∏–≤–µ—Ç {} {}! –¢—ã –Ω–∞–ø–∏—Å–∞–ª: {}".format(update.message.chat.first_name, user_data['emo'],
KeyError: 'emo'
2019-10-20 18:15:35,789 - ERROR - No error handlers are registered, logging exception.
Traceback (most recent call last):
  File "/home/den/projects/megabot/env/lib/python3.7/site-packages/telegram/ext/dispatcher.py", line 372, in process_update
    handler.handle_update(update, self, check, context)
  File "/home/den/projects/megabot/env/lib/python3.7/site-packages/telegram/ext/handler.py", line 120, in handle_update
    return self.callback(dispatcher.bot, update, **optional_args)
  File "bot.py", line 23, in talk_to_me
    user_text = "–ü—Ä–∏–≤–µ—Ç {} {}! –¢—ã –Ω–∞–ø–∏—Å–∞–ª: {}".format(update.message.chat.first_name, user_data['emo'],
KeyError: 'emo'
2019-10-20 18:16:34,451 - INFO - Received signal 2 (SIGINT), stopping...
2019-10-20 18:16:35,404 - WARNING - Exiting immediately!
2019-10-20 18:16:42,388 - INFO - –ë–æ—Ç –∑–∞–ø—É—Å–∫–∞–µ—Ç—Å—è
2019-10-20 18:16:49,114 - ERROR - No error handlers are registered, logging exception.
Traceback (most recent call last):
  File "/home/den/projects/megabot/env/lib/python3.7/site-packages/telegram/ext/dispatcher.py", line 372, in process_update
    handler.handle_update(update, self, check, context)
  File "/home/den/projects/megabot/env/lib/python3.7/site-packages/telegram/ext/handler.py", line 120, in handle_update
    return self.callback(dispatcher.bot, update, **optional_args)
  File "bot.py", line 23, in talk_to_me
    user_text = "–ü—Ä–∏–≤–µ—Ç {} {}! –¢—ã –Ω–∞–ø–∏—Å–∞–ª: {}".format(update.message.chat.first_name, user_data['emo'], update.message.text)
KeyError: 'emo'
2019-10-20 18:17:39,132 - ERROR - Error while getting Updates: urllib3 HTTPError ('Connection aborted.', RemoteDisconnected('Remote end closed connection without response'))
2019-10-20 18:17:39,133 - ERROR - No error handlers are registered, logging exception.
Traceback (most recent call last):
  File "/home/den/projects/megabot/env/lib/python3.7/site-packages/telegram/vendor/ptb_urllib3/urllib3/connectionpool.py", line 617, in urlopen
    chunked=chunked)
  File "/home/den/projects/megabot/env/lib/python3.7/site-packages/telegram/vendor/ptb_urllib3/urllib3/connectionpool.py", line 402, in _make_request
    six.raise_from(e, None)
  File "<string>", line 2, in raise_from
  File "/home/den/projects/megabot/env/lib/python3.7/site-packages/telegram/vendor/ptb_urllib3/urllib3/connectionpool.py", line 398, in _make_request
    httplib_response = conn.getresponse()
  File "/home/den/anaconda3/lib/python3.7/http/client.py", line 1321, in getresponse
    response.begin()
  File "/home/den/anaconda3/lib/python3.7/http/client.py", line 296, in begin
    version, status, reason = self._read_status()
  File "/home/den/anaconda3/lib/python3.7/http/client.py", line 265, in _read_status
    raise RemoteDisconnected("Remote end closed connection without"
http.client.RemoteDisconnected: Remote end closed connection without response

During handling of the above exception, another exception occurred:

Traceback (most recent call last):
  File "/home/den/projects/megabot/env/lib/python3.7/site-packages/telegram/utils/request.py", line 218, in _request_wrapper
    resp = self._con_pool.request(*args, **kwargs)
  File "/home/den/projects/megabot/env/lib/python3.7/site-packages/telegram/vendor/ptb_urllib3/urllib3/request.py", line 70, in request
    **urlopen_kw)
  File "/home/den/projects/megabot/env/lib/python3.7/site-packages/telegram/vendor/ptb_urllib3/urllib3/request.py", line 148, in request_encode_body
    return self.urlopen(method, url, **extra_kw)
  File "/home/den/projects/megabot/env/lib/python3.7/site-packages/telegram/vendor/ptb_urllib3/urllib3/poolmanager.py", line 244, in urlopen
    response = conn.urlopen(method, u.request_uri, **kw)
  File "/home/den/projects/megabot/env/lib/python3.7/site-packages/telegram/vendor/ptb_urllib3/urllib3/connectionpool.py", line 666, in urlopen
    _stacktrace=sys.exc_info()[2])
  File "/home/den/projects/megabot/env/lib/python3.7/site-packages/telegram/vendor/ptb_urllib3/urllib3/util/retry.py", line 347, in increment
    raise six.reraise(type(error), error, _stacktrace)
  File "/home/den/projects/megabot/env/lib/python3.7/site-packages/telegram/vendor/ptb_urllib3/urllib3/packages/six.py", line 685, in reraise
    raise value.with_traceback(tb)
  File "/home/den/projects/megabot/env/lib/python3.7/site-packages/telegram/vendor/ptb_urllib3/urllib3/connectionpool.py", line 617, in urlopen
    chunked=chunked)
  File "/home/den/projects/megabot/env/lib/python3.7/site-packages/telegram/vendor/ptb_urllib3/urllib3/connectionpool.py", line 402, in _make_request
    six.raise_from(e, None)
  File "<string>", line 2, in raise_from
  File "/home/den/projects/megabot/env/lib/python3.7/site-packages/telegram/vendor/ptb_urllib3/urllib3/connectionpool.py", line 398, in _make_request
    httplib_response = conn.getresponse()
  File "/home/den/anaconda3/lib/python3.7/http/client.py", line 1321, in getresponse
    response.begin()
  File "/home/den/anaconda3/lib/python3.7/http/client.py", line 296, in begin
    version, status, reason = self._read_status()
  File "/home/den/anaconda3/lib/python3.7/http/client.py", line 265, in _read_status
    raise RemoteDisconnected("Remote end closed connection without"
telegram.vendor.ptb_urllib3.urllib3.exceptions.ProtocolError: ('Connection aborted.', RemoteDisconnected('Remote end closed connection without response'))

During handling of the above exception, another exception occurred:

Traceback (most recent call last):
  File "/home/den/projects/megabot/env/lib/python3.7/site-packages/telegram/ext/updater.py", line 332, in _network_loop_retry
    if not action_cb():
  File "/home/den/projects/megabot/env/lib/python3.7/site-packages/telegram/ext/updater.py", line 293, in polling_action_cb
    allowed_updates=allowed_updates)
  File "/home/den/projects/megabot/env/lib/python3.7/site-packages/telegram/bot.py", line 66, in decorator
    result = func(self, *args, **kwargs)
  File "/home/den/projects/megabot/env/lib/python3.7/site-packages/telegram/bot.py", line 1983, in get_updates
    result = self._request.post(url, data, timeout=float(read_latency) + float(timeout))
  File "/home/den/projects/megabot/env/lib/python3.7/site-packages/telegram/utils/request.py", line 327, in post
    **urlopen_kwargs)
  File "/home/den/projects/megabot/env/lib/python3.7/site-packages/telegram/utils/request.py", line 224, in _request_wrapper
    raise NetworkError('urllib3 HTTPError {0}'.format(error))
telegram.error.NetworkError: urllib3 HTTPError ('Connection aborted.', RemoteDisconnected('Remote end closed connection without response'))
2019-10-20 18:18:39,323 - ERROR - Error while getting Updates: urllib3 HTTPError ('Connection aborted.', RemoteDisconnected('Remote end closed connection without response'))
2019-10-20 18:18:39,324 - ERROR - No error handlers are registered, logging exception.
Traceback (most recent call last):
  File "/home/den/projects/megabot/env/lib/python3.7/site-packages/telegram/vendor/ptb_urllib3/urllib3/connectionpool.py", line 617, in urlopen
    chunked=chunked)
  File "/home/den/projects/megabot/env/lib/python3.7/site-packages/telegram/vendor/ptb_urllib3/urllib3/connectionpool.py", line 402, in _make_request
    six.raise_from(e, None)
  File "<string>", line 2, in raise_from
  File "/home/den/projects/megabot/env/lib/python3.7/site-packages/telegram/vendor/ptb_urllib3/urllib3/connectionpool.py", line 398, in _make_request
    httplib_response = conn.getresponse()
  File "/home/den/anaconda3/lib/python3.7/http/client.py", line 1321, in getresponse
    response.begin()
  File "/home/den/anaconda3/lib/python3.7/http/client.py", line 296, in begin
    version, status, reason = self._read_status()
  File "/home/den/anaconda3/lib/python3.7/http/client.py", line 265, in _read_status
    raise RemoteDisconnected("Remote end closed connection without"
http.client.RemoteDisconnected: Remote end closed connection without response

During handling of the above exception, another exception occurred:

Traceback (most recent call last):
  File "/home/den/projects/megabot/env/lib/python3.7/site-packages/telegram/utils/request.py", line 218, in _request_wrapper
    resp = self._con_pool.request(*args, **kwargs)
  File "/home/den/projects/megabot/env/lib/python3.7/site-packages/telegram/vendor/ptb_urllib3/urllib3/request.py", line 70, in request
    **urlopen_kw)
  File "/home/den/projects/megabot/env/lib/python3.7/site-packages/telegram/vendor/ptb_urllib3/urllib3/request.py", line 148, in request_encode_body
    return self.urlopen(method, url, **extra_kw)
  File "/home/den/projects/megabot/env/lib/python3.7/site-packages/telegram/vendor/ptb_urllib3/urllib3/poolmanager.py", line 244, in urlopen
    response = conn.urlopen(method, u.request_uri, **kw)
  File "/home/den/projects/megabot/env/lib/python3.7/site-packages/telegram/vendor/ptb_urllib3/urllib3/connectionpool.py", line 666, in urlopen
    _stacktrace=sys.exc_info()[2])
  File "/home/den/projects/megabot/env/lib/python3.7/site-packages/telegram/vendor/ptb_urllib3/urllib3/util/retry.py", line 347, in increment
    raise six.reraise(type(error), error, _stacktrace)
  File "/home/den/projects/megabot/env/lib/python3.7/site-packages/telegram/vendor/ptb_urllib3/urllib3/packages/six.py", line 685, in reraise
    raise value.with_traceback(tb)
  File "/home/den/projects/megabot/env/lib/python3.7/site-packages/telegram/vendor/ptb_urllib3/urllib3/connectionpool.py", line 617, in urlopen
    chunked=chunked)
  File "/home/den/projects/megabot/env/lib/python3.7/site-packages/telegram/vendor/ptb_urllib3/urllib3/connectionpool.py", line 402, in _make_request
    six.raise_from(e, None)
  File "<string>", line 2, in raise_from
  File "/home/den/projects/megabot/env/lib/python3.7/site-packages/telegram/vendor/ptb_urllib3/urllib3/connectionpool.py", line 398, in _make_request
    httplib_response = conn.getresponse()
  File "/home/den/anaconda3/lib/python3.7/http/client.py", line 1321, in getresponse
    response.begin()
  File "/home/den/anaconda3/lib/python3.7/http/client.py", line 296, in begin
    version, status, reason = self._read_status()
  File "/home/den/anaconda3/lib/python3.7/http/client.py", line 265, in _read_status
    raise RemoteDisconnected("Remote end closed connection without"
telegram.vendor.ptb_urllib3.urllib3.exceptions.ProtocolError: ('Connection aborted.', RemoteDisconnected('Remote end closed connection without response'))

During handling of the above exception, another exception occurred:

Traceback (most recent call last):
  File "/home/den/projects/megabot/env/lib/python3.7/site-packages/telegram/ext/updater.py", line 332, in _network_loop_retry
    if not action_cb():
  File "/home/den/projects/megabot/env/lib/python3.7/site-packages/telegram/ext/updater.py", line 293, in polling_action_cb
    allowed_updates=allowed_updates)
  File "/home/den/projects/megabot/env/lib/python3.7/site-packages/telegram/bot.py", line 66, in decorator
    result = func(self, *args, **kwargs)
  File "/home/den/projects/megabot/env/lib/python3.7/site-packages/telegram/bot.py", line 1983, in get_updates
    result = self._request.post(url, data, timeout=float(read_latency) + float(timeout))
  File "/home/den/projects/megabot/env/lib/python3.7/site-packages/telegram/utils/request.py", line 327, in post
    **urlopen_kwargs)
  File "/home/den/projects/megabot/env/lib/python3.7/site-packages/telegram/utils/request.py", line 224, in _request_wrapper
    raise NetworkError('urllib3 HTTPError {0}'.format(error))
telegram.error.NetworkError: urllib3 HTTPError ('Connection aborted.', RemoteDisconnected('Remote end closed connection without response'))
2019-10-20 18:19:39,522 - ERROR - Error while getting Updates: urllib3 HTTPError ('Connection aborted.', RemoteDisconnected('Remote end closed connection without response'))
2019-10-20 18:19:39,523 - ERROR - No error handlers are registered, logging exception.
Traceback (most recent call last):
  File "/home/den/projects/megabot/env/lib/python3.7/site-packages/telegram/vendor/ptb_urllib3/urllib3/connectionpool.py", line 617, in urlopen
    chunked=chunked)
  File "/home/den/projects/megabot/env/lib/python3.7/site-packages/telegram/vendor/ptb_urllib3/urllib3/connectionpool.py", line 402, in _make_request
    six.raise_from(e, None)
  File "<string>", line 2, in raise_from
  File "/home/den/projects/megabot/env/lib/python3.7/site-packages/telegram/vendor/ptb_urllib3/urllib3/connectionpool.py", line 398, in _make_request
    httplib_response = conn.getresponse()
  File "/home/den/anaconda3/lib/python3.7/http/client.py", line 1321, in getresponse
    response.begin()
  File "/home/den/anaconda3/lib/python3.7/http/client.py", line 296, in begin
    version, status, reason = self._read_status()
  File "/home/den/anaconda3/lib/python3.7/http/client.py", line 265, in _read_status
    raise RemoteDisconnected("Remote end closed connection without"
http.client.RemoteDisconnected: Remote end closed connection without response

During handling of the above exception, another exception occurred:

Traceback (most recent call last):
  File "/home/den/projects/megabot/env/lib/python3.7/site-packages/telegram/utils/request.py", line 218, in _request_wrapper
    resp = self._con_pool.request(*args, **kwargs)
  File "/home/den/projects/megabot/env/lib/python3.7/site-packages/telegram/vendor/ptb_urllib3/urllib3/request.py", line 70, in request
    **urlopen_kw)
  File "/home/den/projects/megabot/env/lib/python3.7/site-packages/telegram/vendor/ptb_urllib3/urllib3/request.py", line 148, in request_encode_body
    return self.urlopen(method, url, **extra_kw)
  File "/home/den/projects/megabot/env/lib/python3.7/site-packages/telegram/vendor/ptb_urllib3/urllib3/poolmanager.py", line 244, in urlopen
    response = conn.urlopen(method, u.request_uri, **kw)
  File "/home/den/projects/megabot/env/lib/python3.7/site-packages/telegram/vendor/ptb_urllib3/urllib3/connectionpool.py", line 666, in urlopen
    _stacktrace=sys.exc_info()[2])
  File "/home/den/projects/megabot/env/lib/python3.7/site-packages/telegram/vendor/ptb_urllib3/urllib3/util/retry.py", line 347, in increment
    raise six.reraise(type(error), error, _stacktrace)
  File "/home/den/projects/megabot/env/lib/python3.7/site-packages/telegram/vendor/ptb_urllib3/urllib3/packages/six.py", line 685, in reraise
    raise value.with_traceback(tb)
  File "/home/den/projects/megabot/env/lib/python3.7/site-packages/telegram/vendor/ptb_urllib3/urllib3/connectionpool.py", line 617, in urlopen
    chunked=chunked)
  File "/home/den/projects/megabot/env/lib/python3.7/site-packages/telegram/vendor/ptb_urllib3/urllib3/connectionpool.py", line 402, in _make_request
    six.raise_from(e, None)
  File "<string>", line 2, in raise_from
  File "/home/den/projects/megabot/env/lib/python3.7/site-packages/telegram/vendor/ptb_urllib3/urllib3/connectionpool.py", line 398, in _make_request
    httplib_response = conn.getresponse()
  File "/home/den/anaconda3/lib/python3.7/http/client.py", line 1321, in getresponse
    response.begin()
  File "/home/den/anaconda3/lib/python3.7/http/client.py", line 296, in begin
    version, status, reason = self._read_status()
  File "/home/den/anaconda3/lib/python3.7/http/client.py", line 265, in _read_status
    raise RemoteDisconnected("Remote end closed connection without"
telegram.vendor.ptb_urllib3.urllib3.exceptions.ProtocolError: ('Connection aborted.', RemoteDisconnected('Remote end closed connection without response'))

During handling of the above exception, another exception occurred:

Traceback (most recent call last):
  File "/home/den/projects/megabot/env/lib/python3.7/site-packages/telegram/ext/updater.py", line 332, in _network_loop_retry
    if not action_cb():
  File "/home/den/projects/megabot/env/lib/python3.7/site-packages/telegram/ext/updater.py", line 293, in polling_action_cb
    allowed_updates=allowed_updates)
  File "/home/den/projects/megabot/env/lib/python3.7/site-packages/telegram/bot.py", line 66, in decorator
    result = func(self, *args, **kwargs)
  File "/home/den/projects/megabot/env/lib/python3.7/site-packages/telegram/bot.py", line 1983, in get_updates
    result = self._request.post(url, data, timeout=float(read_latency) + float(timeout))
  File "/home/den/projects/megabot/env/lib/python3.7/site-packages/telegram/utils/request.py", line 327, in post
    **urlopen_kwargs)
  File "/home/den/projects/megabot/env/lib/python3.7/site-packages/telegram/utils/request.py", line 224, in _request_wrapper
    raise NetworkError('urllib3 HTTPError {0}'.format(error))
telegram.error.NetworkError: urllib3 HTTPError ('Connection aborted.', RemoteDisconnected('Remote end closed connection without response'))
2019-10-20 18:20:06,541 - INFO - Received signal 2 (SIGINT), stopping...
2019-10-20 18:20:23,314 - INFO - –ë–æ—Ç –∑–∞–ø—É—Å–∫–∞–µ—Ç—Å—è
2019-10-20 18:20:28,205 - INFO - User: krimea_river, Chat id: 211751313, Message: —ã–ª–≤–æ–ø–∞—ã–¥–ª–ø–≤–æ
2019-10-20 18:20:38,357 - INFO - User: krimea_river, Chat id: 211751313, Message: –≤–∞–≤–∞
2019-10-20 18:20:38,751 - ERROR - Error while getting Updates: urllib3 HTTPError ('Connection aborted.', RemoteDisconnected('Remote end closed connection without response'))
2019-10-20 18:20:38,752 - ERROR - No error handlers are registered, logging exception.
Traceback (most recent call last):
  File "/home/den/projects/megabot/env/lib/python3.7/site-packages/telegram/vendor/ptb_urllib3/urllib3/connectionpool.py", line 617, in urlopen
    chunked=chunked)
  File "/home/den/projects/megabot/env/lib/python3.7/site-packages/telegram/vendor/ptb_urllib3/urllib3/connectionpool.py", line 402, in _make_request
    six.raise_from(e, None)
  File "<string>", line 2, in raise_from
  File "/home/den/projects/megabot/env/lib/python3.7/site-packages/telegram/vendor/ptb_urllib3/urllib3/connectionpool.py", line 398, in _make_request
    httplib_response = conn.getresponse()
  File "/home/den/anaconda3/lib/python3.7/http/client.py", line 1321, in getresponse
    response.begin()
  File "/home/den/anaconda3/lib/python3.7/http/client.py", line 296, in begin
    version, status, reason = self._read_status()
  File "/home/den/anaconda3/lib/python3.7/http/client.py", line 265, in _read_status
    raise RemoteDisconnected("Remote end closed connection without"
http.client.RemoteDisconnected: Remote end closed connection without response

During handling of the above exception, another exception occurred:

Traceback (most recent call last):
  File "/home/den/projects/megabot/env/lib/python3.7/site-packages/telegram/utils/request.py", line 218, in _request_wrapper
    resp = self._con_pool.request(*args, **kwargs)
  File "/home/den/projects/megabot/env/lib/python3.7/site-packages/telegram/vendor/ptb_urllib3/urllib3/request.py", line 70, in request
    **urlopen_kw)
  File "/home/den/projects/megabot/env/lib/python3.7/site-packages/telegram/vendor/ptb_urllib3/urllib3/request.py", line 148, in request_encode_body
    return self.urlopen(method, url, **extra_kw)
  File "/home/den/projects/megabot/env/lib/python3.7/site-packages/telegram/vendor/ptb_urllib3/urllib3/poolmanager.py", line 244, in urlopen
    response = conn.urlopen(method, u.request_uri, **kw)
  File "/home/den/projects/megabot/env/lib/python3.7/site-packages/telegram/vendor/ptb_urllib3/urllib3/connectionpool.py", line 666, in urlopen
    _stacktrace=sys.exc_info()[2])
  File "/home/den/projects/megabot/env/lib/python3.7/site-packages/telegram/vendor/ptb_urllib3/urllib3/util/retry.py", line 347, in increment
    raise six.reraise(type(error), error, _stacktrace)
  File "/home/den/projects/megabot/env/lib/python3.7/site-packages/telegram/vendor/ptb_urllib3/urllib3/packages/six.py", line 685, in reraise
    raise value.with_traceback(tb)
  File "/home/den/projects/megabot/env/lib/python3.7/site-packages/telegram/vendor/ptb_urllib3/urllib3/connectionpool.py", line 617, in urlopen
    chunked=chunked)
  File "/home/den/projects/megabot/env/lib/python3.7/site-packages/telegram/vendor/ptb_urllib3/urllib3/connectionpool.py", line 402, in _make_request
    six.raise_from(e, None)
  File "<string>", line 2, in raise_from
  File "/home/den/projects/megabot/env/lib/python3.7/site-packages/telegram/vendor/ptb_urllib3/urllib3/connectionpool.py", line 398, in _make_request
    httplib_response = conn.getresponse()
  File "/home/den/anaconda3/lib/python3.7/http/client.py", line 1321, in getresponse
    response.begin()
  File "/home/den/anaconda3/lib/python3.7/http/client.py", line 296, in begin
    version, status, reason = self._read_status()
  File "/home/den/anaconda3/lib/python3.7/http/client.py", line 265, in _read_status
    raise RemoteDisconnected("Remote end closed connection without"
telegram.vendor.ptb_urllib3.urllib3.exceptions.ProtocolError: ('Connection aborted.', RemoteDisconnected('Remote end closed connection without response'))

During handling of the above exception, another exception occurred:

Traceback (most recent call last):
  File "/home/den/projects/megabot/env/lib/python3.7/site-packages/telegram/ext/updater.py", line 332, in _network_loop_retry
    if not action_cb():
  File "/home/den/projects/megabot/env/lib/python3.7/site-packages/telegram/ext/updater.py", line 293, in polling_action_cb
    allowed_updates=allowed_updates)
  File "/home/den/projects/megabot/env/lib/python3.7/site-packages/telegram/bot.py", line 66, in decorator
    result = func(self, *args, **kwargs)
  File "/home/den/projects/megabot/env/lib/python3.7/site-packages/telegram/bot.py", line 1983, in get_updates
    result = self._request.post(url, data, timeout=float(read_latency) + float(timeout))
  File "/home/den/projects/megabot/env/lib/python3.7/site-packages/telegram/utils/request.py", line 327, in post
    **urlopen_kwargs)
  File "/home/den/projects/megabot/env/lib/python3.7/site-packages/telegram/utils/request.py", line 224, in _request_wrapper
    raise NetworkError('urllib3 HTTPError {0}'.format(error))
telegram.error.NetworkError: urllib3 HTTPError ('Connection aborted.', RemoteDisconnected('Remote end closed connection without response'))
2019-10-20 18:20:45,234 - INFO - User: krimea_river, Chat id: 211751313, Message: –≤–∞–≤—ã–ø–∞—ã–ø–≤
2019-10-20 18:20:50,750 - INFO - User: krimea_river, Chat id: 211751313, Message: –ø–∫–ø–∫–ø–∫–∫–∫
2019-10-20 18:20:50,856 - INFO - User: krimea_river, Chat id: 211751313, Message: –∫–∫–ø–µ–ø–∫–µ–∫–ø–∞
2019-10-20 18:21:04,242 - INFO - –ü—Ä–∏–≤–µ—Ç üê∂
2019-10-20 18:21:06,992 - INFO - –ü—Ä–∏–≤–µ—Ç üê∂
2019-10-20 18:21:08,099 - INFO - –ü—Ä–∏–≤–µ—Ç üê∂
2019-10-20 18:21:09,702 - INFO - –ü—Ä–∏–≤–µ—Ç üê∂
2019-10-20 18:21:11,111 - INFO - –ü—Ä–∏–≤–µ—Ç üê∂
2019-10-20 18:21:38,945 - ERROR - Error while getting Updates: urllib3 HTTPError ('Connection aborted.', RemoteDisconnected('Remote end closed connection without response'))
2019-10-20 18:21:38,945 - ERROR - No error handlers are registered, logging exception.
Traceback (most recent call last):
  File "/home/den/projects/megabot/env/lib/python3.7/site-packages/telegram/vendor/ptb_urllib3/urllib3/connectionpool.py", line 617, in urlopen
    chunked=chunked)
  File "/home/den/projects/megabot/env/lib/python3.7/site-packages/telegram/vendor/ptb_urllib3/urllib3/connectionpool.py", line 402, in _make_request
    six.raise_from(e, None)
  File "<string>", line 2, in raise_from
  File "/home/den/projects/megabot/env/lib/python3.7/site-packages/telegram/vendor/ptb_urllib3/urllib3/connectionpool.py", line 398, in _make_request
    httplib_response = conn.getresponse()
  File "/home/den/anaconda3/lib/python3.7/http/client.py", line 1321, in getresponse
    response.begin()
  File "/home/den/anaconda3/lib/python3.7/http/client.py", line 296, in begin
    version, status, reason = self._read_status()
  File "/home/den/anaconda3/lib/python3.7/http/client.py", line 265, in _read_status
    raise RemoteDisconnected("Remote end closed connection without"
http.client.RemoteDisconnected: Remote end closed connection without response

During handling of the above exception, another exception occurred:

Traceback (most recent call last):
  File "/home/den/projects/megabot/env/lib/python3.7/site-packages/telegram/utils/request.py", line 218, in _request_wrapper
    resp = self._con_pool.request(*args, **kwargs)
  File "/home/den/projects/megabot/env/lib/python3.7/site-packages/telegram/vendor/ptb_urllib3/urllib3/request.py", line 70, in request
    **urlopen_kw)
  File "/home/den/projects/megabot/env/lib/python3.7/site-packages/telegram/vendor/ptb_urllib3/urllib3/request.py", line 148, in request_encode_body
    return self.urlopen(method, url, **extra_kw)
  File "/home/den/projects/megabot/env/lib/python3.7/site-packages/telegram/vendor/ptb_urllib3/urllib3/poolmanager.py", line 244, in urlopen
    response = conn.urlopen(method, u.request_uri, **kw)
  File "/home/den/projects/megabot/env/lib/python3.7/site-packages/telegram/vendor/ptb_urllib3/urllib3/connectionpool.py", line 666, in urlopen
    _stacktrace=sys.exc_info()[2])
  File "/home/den/projects/megabot/env/lib/python3.7/site-packages/telegram/vendor/ptb_urllib3/urllib3/util/retry.py", line 347, in increment
    raise six.reraise(type(error), error, _stacktrace)
  File "/home/den/projects/megabot/env/lib/python3.7/site-packages/telegram/vendor/ptb_urllib3/urllib3/packages/six.py", line 685, in reraise
    raise value.with_traceback(tb)
  File "/home/den/projects/megabot/env/lib/python3.7/site-packages/telegram/vendor/ptb_urllib3/urllib3/connectionpool.py", line 617, in urlopen
    chunked=chunked)
  File "/home/den/projects/megabot/env/lib/python3.7/site-packages/telegram/vendor/ptb_urllib3/urllib3/connectionpool.py", line 402, in _make_request
    six.raise_from(e, None)
  File "<string>", line 2, in raise_from
  File "/home/den/projects/megabot/env/lib/python3.7/site-packages/telegram/vendor/ptb_urllib3/urllib3/connectionpool.py", line 398, in _make_request
    httplib_response = conn.getresponse()
  File "/home/den/anaconda3/lib/python3.7/http/client.py", line 1321, in getresponse
    response.begin()
  File "/home/den/anaconda3/lib/python3.7/http/client.py", line 296, in begin
    version, status, reason = self._read_status()
  File "/home/den/anaconda3/lib/python3.7/http/client.py", line 265, in _read_status
    raise RemoteDisconnected("Remote end closed connection without"
telegram.vendor.ptb_urllib3.urllib3.exceptions.ProtocolError: ('Connection aborted.', RemoteDisconnected('Remote end closed connection without response'))

During handling of the above exception, another exception occurred:

Traceback (most recent call last):
  File "/home/den/projects/megabot/env/lib/python3.7/site-packages/telegram/ext/updater.py", line 332, in _network_loop_retry
    if not action_cb():
  File "/home/den/projects/megabot/env/lib/python3.7/site-packages/telegram/ext/updater.py", line 293, in polling_action_cb
    allowed_updates=allowed_updates)
  File "/home/den/projects/megabot/env/lib/python3.7/site-packages/telegram/bot.py", line 66, in decorator
    result = func(self, *args, **kwargs)
  File "/home/den/projects/megabot/env/lib/python3.7/site-packages/telegram/bot.py", line 1983, in get_updates
    result = self._request.post(url, data, timeout=float(read_latency) + float(timeout))
  File "/home/den/projects/megabot/env/lib/python3.7/site-packages/telegram/utils/request.py", line 327, in post
    **urlopen_kwargs)
  File "/home/den/projects/megabot/env/lib/python3.7/site-packages/telegram/utils/request.py", line 224, in _request_wrapper
    raise NetworkError('urllib3 HTTPError {0}'.format(error))
telegram.error.NetworkError: urllib3 HTTPError ('Connection aborted.', RemoteDisconnected('Remote end closed connection without response'))
2019-10-20 18:22:39,136 - ERROR - Error while getting Updates: urllib3 HTTPError ('Connection aborted.', RemoteDisconnected('Remote end closed connection without response'))
2019-10-20 18:22:39,136 - ERROR - No error handlers are registered, logging exception.
Traceback (most recent call last):
  File "/home/den/projects/megabot/env/lib/python3.7/site-packages/telegram/vendor/ptb_urllib3/urllib3/connectionpool.py", line 617, in urlopen
    chunked=chunked)
  File "/home/den/projects/megabot/env/lib/python3.7/site-packages/telegram/vendor/ptb_urllib3/urllib3/connectionpool.py", line 402, in _make_request
    six.raise_from(e, None)
  File "<string>", line 2, in raise_from
  File "/home/den/projects/megabot/env/lib/python3.7/site-packages/telegram/vendor/ptb_urllib3/urllib3/connectionpool.py", line 398, in _make_request
    httplib_response = conn.getresponse()
  File "/home/den/anaconda3/lib/python3.7/http/client.py", line 1321, in getresponse
    response.begin()
  File "/home/den/anaconda3/lib/python3.7/http/client.py", line 296, in begin
    version, status, reason = self._read_status()
  File "/home/den/anaconda3/lib/python3.7/http/client.py", line 265, in _read_status
    raise RemoteDisconnected("Remote end closed connection without"
http.client.RemoteDisconnected: Remote end closed connection without response

During handling of the above exception, another exception occurred:

Traceback (most recent call last):
  File "/home/den/projects/megabot/env/lib/python3.7/site-packages/telegram/utils/request.py", line 218, in _request_wrapper
    resp = self._con_pool.request(*args, **kwargs)
  File "/home/den/projects/megabot/env/lib/python3.7/site-packages/telegram/vendor/ptb_urllib3/urllib3/request.py", line 70, in request
    **urlopen_kw)
  File "/home/den/projects/megabot/env/lib/python3.7/site-packages/telegram/vendor/ptb_urllib3/urllib3/request.py", line 148, in request_encode_body
    return self.urlopen(method, url, **extra_kw)
  File "/home/den/projects/megabot/env/lib/python3.7/site-packages/telegram/vendor/ptb_urllib3/urllib3/poolmanager.py", line 244, in urlopen
    response = conn.urlopen(method, u.request_uri, **kw)
  File "/home/den/projects/megabot/env/lib/python3.7/site-packages/telegram/vendor/ptb_urllib3/urllib3/connectionpool.py", line 666, in urlopen
    _stacktrace=sys.exc_info()[2])
  File "/home/den/projects/megabot/env/lib/python3.7/site-packages/telegram/vendor/ptb_urllib3/urllib3/util/retry.py", line 347, in increment
    raise six.reraise(type(error), error, _stacktrace)
  File "/home/den/projects/megabot/env/lib/python3.7/site-packages/telegram/vendor/ptb_urllib3/urllib3/packages/six.py", line 685, in reraise
    raise value.with_traceback(tb)
  File "/home/den/projects/megabot/env/lib/python3.7/site-packages/telegram/vendor/ptb_urllib3/urllib3/connectionpool.py", line 617, in urlopen
    chunked=chunked)
  File "/home/den/projects/megabot/env/lib/python3.7/site-packages/telegram/vendor/ptb_urllib3/urllib3/connectionpool.py", line 402, in _make_request
    six.raise_from(e, None)
  File "<string>", line 2, in raise_from
  File "/home/den/projects/megabot/env/lib/python3.7/site-packages/telegram/vendor/ptb_urllib3/urllib3/connectionpool.py", line 398, in _make_request
    httplib_response = conn.getresponse()
  File "/home/den/anaconda3/lib/python3.7/http/client.py", line 1321, in getresponse
    response.begin()
  File "/home/den/anaconda3/lib/python3.7/http/client.py", line 296, in begin
    version, status, reason = self._read_status()
  File "/home/den/anaconda3/lib/python3.7/http/client.py", line 265, in _read_status
    raise RemoteDisconnected("Remote end closed connection without"
telegram.vendor.ptb_urllib3.urllib3.exceptions.ProtocolError: ('Connection aborted.', RemoteDisconnected('Remote end closed connection without response'))

During handling of the above exception, another exception occurred:

Traceback (most recent call last):
  File "/home/den/projects/megabot/env/lib/python3.7/site-packages/telegram/ext/updater.py", line 332, in _network_loop_retry
    if not action_cb():
  File "/home/den/projects/megabot/env/lib/python3.7/site-packages/telegram/ext/updater.py", line 293, in polling_action_cb
    allowed_updates=allowed_updates)
  File "/home/den/projects/megabot/env/lib/python3.7/site-packages/telegram/bot.py", line 66, in decorator
    result = func(self, *args, **kwargs)
  File "/home/den/projects/megabot/env/lib/python3.7/site-packages/telegram/bot.py", line 1983, in get_updates
    result = self._request.post(url, data, timeout=float(read_latency) + float(timeout))
  File "/home/den/projects/megabot/env/lib/python3.7/site-packages/telegram/utils/request.py", line 327, in post
    **urlopen_kwargs)
  File "/home/den/projects/megabot/env/lib/python3.7/site-packages/telegram/utils/request.py", line 224, in _request_wrapper
    raise NetworkError('urllib3 HTTPError {0}'.format(error))
telegram.error.NetworkError: urllib3 HTTPError ('Connection aborted.', RemoteDisconnected('Remote end closed connection without response'))
2019-10-20 18:22:46,056 - INFO - Received signal 2 (SIGINT), stopping...
